<?xml version="1.0"?>
<robot name="robot">

  <link name="base_footprint">
  </link>

  <!-- Body -->
  <link name="base_link">
    <visual>
      <geometry>
        <cylinder length="0.155" radius="0.178"/>
      </geometry>
    </visual>

    <collision>
      <geometry>
        <cylinder length="0.155" radius="0.178"/>
    </geometry>
    </collision>

    <inertial>
      <mass value="10.5"/>
      <origin rpy="0 0 0" xyz="0 0 0"/>
      <inertia ixx="0.0008333333333333335" ixy="0" ixz="0" iyy="0.0008333333333333335" iyz="0" izz="0.0008333333333333335"/>
    </inertial>

  </link>

  <joint name="base_link_joint" type="fixed">
    <origin rpy="0 0 0" xyz="0 0 0" />
    <parent link="base_footprint" />
    <child link="base_link" />
  </joint>

  <!-- Wheel Left -->
  <link name="left_wheel">      
      <visual>
        <origin rpy="0 1.5707 1.5707" xyz="0 0 0"/>
        <geometry>
          <cylinder length="0.025" radius="0.03"/>
        </geometry>
        <material name="red"/>
      </visual>

      <collision>
        <origin rpy="0 1.5707 1.5707" xyz="0 0 0"/>
        <geometry>
          <cylinder length="0.025" radius="0.03"/>
        </geometry>
      </collision>

      <inertial>
        <origin rpy="0 1.5707 1.5707" xyz="0 0 0"/>
        <mass value="5"/>
        <inertia ixx="0.104192375" ixy="0.0" ixz="0.0" 
        iyy="0.104192375" iyz="0.0" izz="0.166341"/>
        
      </inertial>

  </link>


  <joint name="joint_left_wheel" type="continuous">
    <origin rpy="0 0 0" xyz="0 0.15 -0.0775"/>
    <parent link="base_link"/>
    <child link="left_wheel"/>
    <axis rpy="0 0 0" xyz="0 1 0"/>
    <limit effort="10000" velocity="1000"/>
    <joint_properties damping="1.0" friction="1.0"/>
  </joint>



  <!-- Wheel Right -->
  <link name="right_wheel">      
      <visual>
        <origin rpy="0 1.5707 1.5707" xyz="0 0 0"/>
        <geometry>
          <cylinder length="0.025" radius="0.03"/>
        </geometry>
        <material name="red"/>
      </visual>

      <collision>
        <origin rpy="0 1.5707 1.5707" xyz="0 0 0"/>
        <geometry>
          <cylinder length="0.025" radius="0.03"/>
        </geometry>
      </collision>

      <inertial>
        <origin rpy="0 1.5707 1.5707" xyz="0 0 0"/>
        <mass value="5"/>
        <inertia ixx="0.104192375" ixy="0.0" ixz="0.0" 
        iyy="0.104192375" iyz="0.0" izz="0.166341"/>
        
      </inertial>

  </link>


  <joint name="joint_right_wheel" type="continuous">
    <origin rpy="0 0 0" xyz="0 -0.15 -0.0775"/>
    <parent link="base_link"/>
    <child link="right_wheel"/>
    <axis rpy="0 0 0" xyz="0 1 0"/>
    <limit effort="10000" velocity="1000"/>
    <joint_properties damping="1.0" friction="1.0"/>
  </joint>


<!-- Preguntar como divido el peso xd -->
  <!-- Caster Wheel Front -->
  <link name="front_yaw_link">
    <visual>
        <origin rpy="0 1.5707 1.5707" xyz="0 0 0"/>
        <geometry>
          <cylinder length="0.005" radius="0.03"/>
        </geometry>
        <material name="blue"/>
      </visual>

      <collision>
        <origin rpy="0 1.5707 1.5707" xyz="0 0 0"/>
        <geometry>
          <cylinder length="0.005" radius="0.03"/>
        </geometry>
      </collision>

      <inertial>
          <origin rpy="0 1.5707 1.5707" xyz="0 0 0"/>
          <mass value="0.001"/>
          <inertia ixx="5.145833333333334e-09" ixy="0" ixz="0" iyy="5.145833333333334e-09" iyz="0" izz="1.0125000000000003e-08"/>
      </inertial>
  </link>

  <joint name="front_yaw_joint" type="continuous">
    <origin rpy="0 0 0" xyz="0.12 0 -0.0775" />
    <parent link="base_link" />
    <child link="front_yaw_link" />
    <axis xyz="0 0 1" />
    <limit effort="1000.0" velocity="100.0" />
    <dynamics damping="0.0" friction="0.1"/>
  </joint>



  <link name="front_roll_link">
      <visual>
        <origin rpy="0 1.5707 1.5707" xyz="0 0 0"/>
        <geometry>
          <cylinder length="0.005" radius="0.03"/>
        </geometry>
        <material name="red"/>
      </visual>

      <collision>
        <origin rpy="0 1.5707 1.5707" xyz="0 0 0"/>
        <geometry>
          <cylinder length="0.005" radius="0.03"/>
        </geometry>
      </collision>

      <inertial>
          <origin rpy="0 1.5707 1.5707" xyz="0 0 0"/>
          <mass value="0.001"/>
          <inertia ixx="5.145833333333334e-09" ixy="0" ixz="0" iyy="5.145833333333334e-09" iyz="0" izz="1.0125000000000003e-08"/>
      </inertial>
  </link>

  <joint name="front_roll_joint" type="continuous">
    <origin rpy="0 0 0" xyz="0 0 0" />
    <parent link="front_yaw_link" />
    <child link="front_roll_link" />
    <axis xyz="1 0 0" />
    <limit effort="1000.0" velocity="100.0" />
    <dynamics damping="0.0" friction="0.1"/>
  </joint>


  <link name="front_pitch_link">
    <visual>
      <origin rpy="0 1.5707 1.5707" xyz="0 0 0"/>
      <geometry>
        <sphere radius="0.030"/>
      </geometry>
      <material name="green_dark"/>
    </visual>

    <collision>
      <origin rpy="0 1.5707 1.5707" xyz="0 0 0"/>
      <geometry>
        <sphere radius="0.030"/>
      </geometry>
    </collision>

    <inertial>
        <origin rpy="0 1.5707 1.5707" xyz="0 0 0"/>
        <mass value="0.001"/>
        <inertia ixx="4e-08" ixy="0" ixz="0" iyy="4e-08" iyz="0" izz="4e-08"/>
    </inertial>
  </link>


  <joint name="front_pitch_joint" type="continuous">
    <origin rpy="0 0 0" xyz="0 0 0" />
    <parent link="front_roll_link" />
    <child link="front_pitch_link" />
    <axis xyz="0 1 0" />
    <limit effort="1000.0" velocity="100.0" />
    <dynamics damping="0.0" friction="0.1"/>
  </joint>

 <!-- Back Caster Wheel -->
 
<!-- Caster Wheel Back -->
  <link name="back_yaw_link">
    <visual>
        <origin rpy="0 1.5707 1.5707" xyz="0 0 0"/>
        <geometry>
          <cylinder length="0.005" radius="0.03"/>
        </geometry>
        <material name="blue"/>
      </visual>

      <collision>
        <origin rpy="0 1.5707 1.5707" xyz="0 0 0"/>
        <geometry>
          <cylinder length="0.005" radius="0.03"/>
        </geometry>
      </collision>

      <inertial>
          <origin rpy="0 1.5707 1.5707" xyz="0 0 0"/>
          <mass value="0.001"/>
          <inertia ixx="5.145833333333334e-09" ixy="0" ixz="0" iyy="5.145833333333334e-09" iyz="0" izz="1.0125000000000003e-08"/>
      </inertial>
  </link>

  <joint name="back_yaw_joint" type="continuous">
    <origin rpy="0 0 0" xyz="-0.12 0 -0.0775" />
    <parent link="base_link" />
    <child link="back_yaw_link" />
    <axis xyz="0 0 1" />
    <limit effort="1000.0" velocity="100.0" />
    <dynamics damping="0.0" friction="0.1"/>
  </joint>


  <link name="back_roll_link">
      <visual>
        <origin rpy="0 1.5707 1.5707" xyz="0 0 0"/>
        <geometry>
          <cylinder length="0.005" radius="0.03"/>
        </geometry>
        <material name="blue"/>
      </visual>

      <collision>
        <origin rpy="0 1.5707 1.5707" xyz="0 0 0"/>
        <geometry>
          <cylinder length="0.005" radius="0.03"/>
        </geometry>
      </collision>

      <inertial>
          <origin rpy="0 1.5707 1.5707" xyz="0 0 0"/>
          <mass value="0.001"/>
          <inertia ixx="5.145833333333334e-09" ixy="0" ixz="0" iyy="5.145833333333334e-09" iyz="0" izz="1.0125000000000003e-08"/>
      </inertial>
  </link>

  <joint name="back_roll_joint" type="continuous">
    <origin rpy="0 0 0" xyz="0 0 0" />
    <parent link="back_yaw_link" />
    <child link="back_roll_link" />
    <axis xyz="1 0 0" />
    <limit effort="1000.0" velocity="100.0" />
    <dynamics damping="0.0" friction="0.1"/>
  </joint>


  <link name="back_pitch_link">
    <visual>
      <origin rpy="0 1.5707 1.5707" xyz="0 0 0"/>
      <geometry>
        <sphere radius="0.03"/>
      </geometry>
      <material name="blue"/>
    </visual>

    <collision>
      <origin rpy="0 1.5707 1.5707" xyz="0 0 0"/>
      <geometry>
        <sphere radius="0.03"/>
      </geometry>
    </collision>

    <inertial>
        <origin rpy="0 1.5707 1.5707" xyz="0 0 0"/>
        <mass value="0.001"/>
        <inertia ixx="4e-08" ixy="0" ixz="0" iyy="4e-08" iyz="0" izz="4e-08"/>
    </inertial>
  </link>


  <joint name="back_pitch_joint" type="continuous">
    <origin rpy="0 0 0" xyz="0 0 0" />
    <parent link="back_roll_link" />
    <child link="back_pitch_link" />
    <axis xyz="0 1 0" />
    <limit effort="1000.0" velocity="100.0" />
    <dynamics damping="0.0" friction="0.1"/>
  </joint>

  <link name="right_front_support_link">      
      <visual>
        <origin rpy="0 0 0" xyz="0 0 0"/>
        <geometry>
          <cylinder length="0.220" radius="0.01"/>
        </geometry>
        <material name="red"/>
      </visual>

      <collision>
        <origin rpy="0 0 0" xyz="0 0 0"/>
        <geometry>
          <cylinder length="0.220" radius="0.01"/>
        </geometry>
      </collision>

      <inertial>
        <origin rpy="0 0 0" xyz="0 0 0"/>
        <mass value="5"/>
        <inertia ixx="0.104192375" ixy="0.0" ixz="0.0" 
        iyy="0.104192375" iyz="0.0" izz="0.166341"/>
        
      </inertial>

  </link>


  <joint name="joint_bar_1" type="fixed">
    <origin rpy="0 0 0" xyz="0.05 -0.120 0.185"/>
    <parent link="base_link"/>
    <child link="right_front_support_link"/>
    <axis rpy="0 0 0" xyz="0 1 0"/>
    <limit effort="10000" velocity="1000"/>
    <joint_properties damping="1.0" friction="1.0"/>
  </joint>


  <link name="right_back_support_link">      
      <visual>
        <origin rpy="0 0 0" xyz="0 0 0"/>
        <geometry>
          <cylinder length="0.220" radius="0.01"/>
        </geometry>
        <material name="red"/>
      </visual>

      <collision>
        <origin rpy="0 0 0" xyz="0 0 0"/>
        <geometry>
          <cylinder length="0.220" radius="0.01"/>
        </geometry>
      </collision>

      <inertial>
        <origin rpy="0 0 0" xyz="0 0 0"/>
        <mass value="5"/>
        <inertia ixx="0.104192375" ixy="0.0" ixz="0.0" 
        iyy="0.104192375" iyz="0.0" izz="0.166341"/>
        
      </inertial>

  </link>


  <joint name="joint_bar_2" type="fixed">
    <origin rpy="0 0 0" xyz="-0.05 -0.120 0.185"/>
    <parent link="base_link"/>
    <child link="right_back_support_link"/>
  </joint>

  <link name="left_front_support_link">      
      <visual>
        <origin rpy="0 0 0" xyz="0 0 0"/>
        <geometry>
          <cylinder length="0.220" radius="0.01"/>
        </geometry>
        <material name="red"/>
      </visual>

      <collision>
        <origin rpy="0 0 0" xyz="0 0 0"/>
        <geometry>
          <cylinder length="0.220" radius="0.01"/>
        </geometry>
      </collision>

      <inertial>
        <origin rpy="0 0 0" xyz="0 0 0"/>
        <mass value="5"/>
        <inertia ixx="0.104192375" ixy="0.0" ixz="0.0" 
        iyy="0.104192375" iyz="0.0" izz="0.166341"/>
        
      </inertial>
  </link>

  <joint name="joint_bar_3" type="fixed">
    <origin rpy="0 0 0" xyz="0.05 0.120 0.185"/>
    <parent link="base_link"/>
    <child link="left_front_support_link"/>
    <axis rpy="0 0 0" xyz="0 1 0"/>
    <limit effort="10000" velocity="1000"/>
    <joint_properties damping="1.0" friction="1.0"/>
  </joint>


  <link name="left_back_support_link">      
      <visual>
        <origin rpy="0 0 0" xyz="0 0 0"/>
        <geometry>
          <cylinder length="0.220" radius="0.01"/>
        </geometry>
        <material name="red"/>
      </visual>

      <collision>
        <origin rpy="0 0 0" xyz="0 0 0"/>
        <geometry>
          <cylinder length="0.220" radius="0.01"/>
        </geometry>
      </collision>

      <inertial>
        <origin rpy="0 0 0" xyz="0 0 0"/>
        <mass value="5"/>
        <inertia ixx="0.104192375" ixy="0.0" ixz="0.0" 
        iyy="0.104192375" iyz="0.0" izz="0.166341"/>
        
      </inertial>

  </link>

  <joint name="joint_bar_4" type="fixed">
    <origin rpy="0 0 0" xyz="-0.05 0.120 0.185"/>
    <parent link="base_link"/>
    <child link="left_back_support_link"/>
    <axis rpy="0 0 0" xyz="0 1 0"/>
    <limit effort="10000" velocity="1000"/>
    <joint_properties damping="1.0" friction="1.0"/>
  </joint>

  <link name="head">      
      <visual>
        <origin rpy="0 0 0" xyz="0 0 0"/>
        <geometry>
          <cylinder length="0.09" radius="0.160"/>
        </geometry>
        <material name="grey"/>
      </visual>

      <collision>
        <origin rpy="0 0 0" xyz="0 0 0"/>
        <geometry>
          <cylinder length="0.09" radius="0.160"/>
        </geometry>
      </collision>

      <inertial>
        <origin rpy="0 0 0" xyz="0 0 0"/>
        <mass value="5"/>
        <inertia ixx="0.104192375" ixy="0.0" ixz="0.0" 
        iyy="0.104192375" iyz="0.0" izz="0.166341"/>
        
      </inertial>

  </link>

  <joint name="head_joint" type="fixed">
    <origin rpy="0 0 0" xyz="0 0 0.2975"/>
    <parent link="base_link"/>
    <child link="head"/>
    <axis rpy="0 0 0" xyz="0 1 0"/>
    <limit effort="10000" velocity="1000"/>
    <joint_properties damping="1.0" friction="1.0"/>
  </joint> 

</robot>