<?xml version="1.0"?>
<robot name="Morty">

  <!-- <link name="base_footprint">
  </link> -->

  <!-- Body -->
  <link name="base_link">
    <visual>
      <geometry>
        <cylinder length="0.155" radius="0.178"/>
      </geometry>
    </visual>

    <collision>
      <geometry>
        <cylinder length="0.155" radius="0.178"/>
    </geometry>
    </collision>

    <inertial>
      <mass value="5.5"/>
      <origin rpy="0 0 0" xyz="0 0 0"/>
    <inertia ixx="0.054576958333333335" ixy="0.0" ixz="0.0" iyy="0.054576958333333335" iyz="0.0" izz="0.08713099999999999" />
    </inertial>

  </link>

  <!-- <joint name="base_link_joint" type="fixed">
    <origin rpy="0 0 0" xyz="0 0 0" />
    <parent link="base_footprint" />
    <child link="base_link" />
  </joint> -->

  <!-- Wheel Left -->
  <link name="left_wheel">      
      <visual>
        <origin rpy="0 1.5707 1.5707" xyz="0 0 0"/>
        <geometry>
          <cylinder length="0.025" radius="0.03"/>
        </geometry>
        <material name="red"/>
      </visual>

      <collision>
        <origin rpy="0 1.5707 1.5707" xyz="0 0 0"/>
        <geometry>
          <cylinder length="0.025" radius="0.03"/>
        </geometry>
      </collision>

      <inertial>
        <origin rpy="0 1.5707 1.5707" xyz="0 0 0"/>
        <mass value="2.5"/>
        <inertia ixx="0.0006927083333333334" ixy="0.0" ixz="0.0" iyy="0.0006927083333333334" iyz="0.0" izz="0.001125" />
      </inertial>
  </link>

  
  <joint name="joint_left_wheel" type="continuous">
    <origin rpy="0 0 0" xyz="0 0.15 -0.0775"/>
    <parent link="base_link"/>
    <child link="left_wheel"/>
    <axis rpy="0 0 0" xyz="0 1 0"/>
    <limit effort="10000" velocity="1000"/>
    <joint_properties damping="1.0" friction="1.0"/>
  </joint>

  <!-- Wheel Right -->
  <link name="right_wheel">      
      <visual>
        <origin rpy="0 1.5707 1.5707" xyz="0 0 0"/>
        <geometry>
          <cylinder length="0.025" radius="0.03"/>
        </geometry>
        <material name="red"/>
      </visual>

      <collision>
        <origin rpy="0 1.5707 1.5707" xyz="0 0 0"/>
        <geometry>
          <cylinder length="0.025" radius="0.03"/>
        </geometry>
      </collision>

      <inertial>
        <origin rpy="0 1.5707 1.5707" xyz="0 0 0"/>
        <mass value="2.5"/>
        <inertia ixx="0.0006927083333333334" ixy="0.0" ixz="0.0" iyy="0.0006927083333333334" iyz="0.0" izz="0.001125" />
       </inertial>

  </link>


  <joint name="joint_right_wheel" type="continuous">
    <origin rpy="0 0 0" xyz="0 -0.15 -0.0775"/>
    <parent link="base_link"/>
    <child link="right_wheel"/>
    <axis rpy="0 0 0" xyz="0 1 0"/>
    <limit effort="10000" velocity="1000"/>
    <joint_properties damping="1.0" friction="1.0"/>
  </joint>


<!-- Preguntar como divido el peso xd -->
  <!-- Caster Wheel Front -->
  <link name="front_yaw_link">
        <visual>
            <origin rpy="0 1.5707 1.5707" xyz="0 0 0"/>
            <geometry>
            <cylinder length="0.005" radius="0.0045000000000000005"/>
            </geometry>
            <material name="blue"/>
        </visual>

      <collision>
            <origin rpy="0 1.5707 1.5707" xyz="0 0 0"/>
            <geometry>
            <cylinder length="0.005" radius="0.0045000000000000005"/>
            </geometry>
      </collision>

      <inertial>
          <origin rpy="0 1.5707 1.5707" xyz="0 0 0"/>
          <mass value="0.5"/>
          <inertia ixx="0.00011354166666666666" ixy="0.0" ixz="0.0" iyy="0.00011354166666666666" iyz="0.0" izz="0.000225" />
      </inertial>
  </link>

    <gazebo reference="front_yaw_link">
        <material>Gazebo/Blue</material>
    </gazebo>

  <joint name="front_yaw_joint" type="continuous">
    <origin rpy="0 0 0" xyz="0.12 0 -0.0775" />
    <parent link="base_link" />
    <child link="front_yaw_link" />
    <axis xyz="0 0 1" />
    <limit effort="1000.0" velocity="100.0" />
    <dynamics damping="0.0" friction="0.1"/>
  </joint>

  <link name="front_roll_link">
      <visual>
        <origin rpy="0 1.5707 1.5707" xyz="0 0 0"/>
        <geometry>
          <cylinder length="0.005"  radius="0.0045000000000000005"/>
        </geometry>
        <material name="red"/>
      </visual>

      <collision>
        <origin rpy="0 1.5707 1.5707" xyz="0 0 0"/>
        <geometry>
          <cylinder length="0.005"  radius="0.0045000000000000005"/>
        </geometry>
      </collision>

      <inertial>
          <origin rpy="0 1.5707 1.5707" xyz="0 0 0"/>
          <mass value="0.5"/>
          <inertia ixx="0.00011354166666666666" ixy="0.0" ixz="0.0" iyy="0.00011354166666666666" iyz="0.0" izz="0.000225" />
      </inertial>
  </link>

    <gazebo reference="front_roll_link">
        <material>Gazebo/Red</material>
    </gazebo>


  <joint name="front_roll_joint" type="continuous">
    <origin rpy="0 0 0" xyz="0 0 0" />
    <parent link="front_yaw_link" />
    <child link="front_roll_link" />
    <axis xyz="1 0 0" />
    <limit effort="1000.0" velocity="100.0" />
    <dynamics damping="0.0" friction="0.1"/>
  </joint>


  <link name="front_pitch_link">
    <visual>
      <origin rpy="0 1.5707 1.5707" xyz="0 0 0"/>
      <geometry>
        <sphere radius="0.030"/>
      </geometry>
      <material name="green_dark"/>
    </visual>

    <collision>
      <origin rpy="0 1.5707 1.5707" xyz="0 0 0"/>
      <geometry>
        <sphere radius="0.030"/>
      </geometry>
    </collision>

    <inertial>
        <origin rpy="0 1.5707 1.5707" xyz="0 0 0"/>
        <mass value="0.5"/>
        <inertia  ixx="0.00017999999999999998" ixy="0.0" ixz="0.0" iyy="0.00017999999999999998" iyz="0.0" izz="0.00017999999999999998"/>
    </inertial>
  </link>

  <joint name="front_pitch_joint" type="continuous">
    <origin rpy="0 0 0" xyz="0 0 0" />
    <parent link="front_roll_link" />
    <child link="front_pitch_link" />
    <axis xyz="0 1 0" />
    <limit effort="1000.0" velocity="100.0" />
    <dynamics damping="0.0" friction="0.1"/>
  </joint>

 <!-- Back Caster Wheel -->
   <link name="back_yaw_link">
    <visual>
        <origin rpy="0 1.5707 1.5707" xyz="0 0 0"/>
        <geometry>
          <cylinder length="0.005"  radius="0.0045000000000000005"/>
        </geometry>
        <material name="blue"/>
      </visual>

      <collision>
        <origin rpy="0 1.5707 1.5707" xyz="0 0 0"/>
        <geometry>
          <cylinder length="0.005"  radius="0.0045000000000000005"/>
        </geometry>
      </collision>

      <inertial>
          <origin rpy="0 1.5707 1.5707" xyz="0 0 0"/>
          <mass value="0.5"/>
          <inertia ixx="0.00011354166666666666" ixy="0.0" ixz="0.0" iyy="0.00011354166666666666" iyz="0.0" izz="0.000225" />
      </inertial>
  </link>

    <gazebo reference="back_yaw_link">
        <material>Gazebo/Blue</material>
    </gazebo>


  <joint name="back_yaw_joint" type="continuous">
    <origin rpy="0 0 0" xyz="-0.12 0 -0.0775" />
    <parent link="base_link" />
    <child link="back_yaw_link" />
    <axis xyz="0 0 1" />
    <limit effort="1000.0" velocity="100.0" />
    <dynamics damping="0.0" friction="0.1"/>
  </joint>


  <link name="back_roll_link">
      <visual>
        <origin rpy="0 1.5707 1.5707" xyz="0 0 0"/>
        <geometry>
          <cylinder length="0.005"  radius="0.0045000000000000005"/>
        </geometry>
        <material name="blue"/>
      </visual>

      <collision>
        <origin rpy="0 1.5707 1.5707" xyz="0 0 0"/>
        <geometry>
          <cylinder length="0.005"  radius="0.0045000000000000005"/>
        </geometry>
      </collision>

      <inertial>
          <origin rpy="0 1.5707 1.5707" xyz="0 0 0"/>
          <mass value="0.5"/>
          <inertia ixx="0.00011354166666666666" ixy="0.0" ixz="0.0" iyy="0.00011354166666666666" iyz="0.0" izz="0.000225" />
      </inertial>
  </link>

   <gazebo reference="back_roll_link">
        <material>Gazebo/Red</material>
    </gazebo>

  <joint name="back_roll_joint" type="continuous">
    <origin rpy="0 0 0" xyz="0 0 0" />
    <parent link="back_yaw_link" />
    <child link="back_roll_link" />
    <axis xyz="1 0 0" />
    <limit effort="1000.0" velocity="100.0" />
    <dynamics damping="0.0" friction="0.1"/>
  </joint>


  <link name="back_pitch_link">
    <visual>
      <origin rpy="0 1.5707 1.5707" xyz="0 0 0"/>
      <geometry>
        <sphere radius="0.030"/>
      </geometry>
      <material name="blue"/>
    </visual>

    <collision>
      <origin rpy="0 1.5707 1.5707" xyz="0 0 0"/>
      <geometry>
        <sphere radius="0.030"/>
      </geometry>
    </collision>

    <inertial>
        <origin rpy="0 1.5707 1.5707" xyz="0 0 0"/>
        <mass value="0.5"/>
        <inertia  ixx="0.00017999999999999998" ixy="0.0" ixz="0.0" iyy="0.00017999999999999998" iyz="0.0" izz="0.00017999999999999998"/>
    </inertial>
  </link>

  <gazebo reference="left_wheel">
    <kp>1000000000000000000000000000.0</kp>
    <kd>1000000000000000000000000000.0</kd>
    <mu1>10.0</mu1>
    <mu2>10.0</mu2>
    <material>Gazebo/Green</material>
  </gazebo>

  <gazebo reference="right_wheel">
    <kp>1000000000000000000000000000.0</kp>
    <kd>1000000000000000000000000000.0</kd>
    <mu1>10.0</mu1>
    <mu2>10.0</mu2>
    <material>Gazebo/Orange</material>
  </gazebo>

  <gazebo reference="front_pitch_link">
    <kp>1000000000000000000000000000.0</kp>
    <kd>1000000000000000000000000000.0</kd>
    <mu1>0.5</mu1>
    <mu2>0.5</mu2>
    <material>Gazebo/Purple</material>
  </gazebo>

  <gazebo reference="back_pitch_link">
    <kp>1000000000000000000000000000.0</kp>
    <kd>1000000000000000000000000000.0</kd>
    <mu1>0.5</mu1>
    <mu2>0.5</mu2>
    <material>Gazebo/Yellow</material>
  </gazebo>


  <joint name="back_pitch_joint" type="continuous">
    <origin rpy="0 0 0" xyz="0 0 0" />
    <parent link="back_roll_link" />
    <child link="back_pitch_link" />
    <axis xyz="0 1 0" />
    <limit effort="1000.0" velocity="100.0" />
    <dynamics damping="0.0" friction="0.1"/>
  </joint>

  <link name="right_front_support_link">      
      <visual>
        <origin rpy="0 0 0" xyz="0 0 0"/>
        <geometry>
          <cylinder length="0.220" radius="0.01"/>
        </geometry>
        <material name="red"/>
      </visual>

      <collision>
        <origin rpy="0 0 0" xyz="0 0 0"/>
        <geometry>
          <cylinder length="0.220" radius="0.01"/>
        </geometry>
      </collision>

      <inertial>
        <origin rpy="0 0 0" xyz="0 0 0"/>
        <mass value="0.25"/>
        <inertia ixx="0.0010145833333333333" ixy="0.0" ixz="0.0" iyy="0.0010145833333333333" iyz="0.0" izz="1.25e-05" />
      </inertial>

  </link>


  <joint name="joint_bar_1" type="fixed">
    <origin rpy="0 0 0" xyz="0.05 -0.120 0.185"/>
    <parent link="base_link"/>
    <child link="right_front_support_link"/>
    <axis rpy="0 0 0" xyz="0 1 0"/>
    <limit effort="10000" velocity="1000"/>
    <joint_properties damping="1.0" friction="1.0"/>
  </joint>


  <link name="right_back_support_link">      
      <visual>
        <origin rpy="0 0 0" xyz="0 0 0"/>
        <geometry>
          <cylinder length="0.220" radius="0.01"/>
        </geometry>
        <material name="red"/>
      </visual>

      <collision>
        <origin rpy="0 0 0" xyz="0 0 0"/>
        <geometry>
          <cylinder length="0.220" radius="0.01"/>
        </geometry>
      </collision>

      <inertial>
        <origin rpy="0 0 0" xyz="0 0 0"/>
        <mass value="0.25"/>
        <inertia ixx="0.0010145833333333333" ixy="0.0" ixz="0.0" iyy="0.0010145833333333333" iyz="0.0" izz="1.25e-05" />
      </inertial>

  </link>


  <joint name="joint_bar_2" type="fixed">
    <origin rpy="0 0 0" xyz="-0.05 -0.120 0.185"/>
    <parent link="base_link"/>
    <child link="right_back_support_link"/>
  </joint>

  <link name="left_front_support_link">      
      <visual>
        <origin rpy="0 0 0" xyz="0 0 0"/>
        <geometry>
          <cylinder length="0.220" radius="0.01"/>
        </geometry>
        <material name="red"/>
      </visual>

      <collision>
        <origin rpy="0 0 0" xyz="0 0 0"/>
        <geometry>
          <cylinder length="0.220" radius="0.01"/>
        </geometry>
      </collision>

      <inertial>
        <origin rpy="0 0 0" xyz="0 0 0"/>
        <mass value="0.25"/>
        <inertia ixx="0.0010145833333333333" ixy="0.0" ixz="0.0" iyy="0.0010145833333333333" iyz="0.0" izz="1.25e-05" />
      </inertial>
  </link>

  <joint name="joint_bar_3" type="fixed">
    <origin rpy="0 0 0" xyz="0.05 0.120 0.185"/>
    <parent link="base_link"/>
    <child link="left_front_support_link"/>
    <axis rpy="0 0 0" xyz="0 1 0"/>
    <limit effort="10000" velocity="1000"/>
    <joint_properties damping="1.0" friction="1.0"/>
  </joint>


  <link name="left_back_support_link">      
      <visual>
        <origin rpy="0 0 0" xyz="0 0 0"/>
        <geometry>
          <cylinder length="0.220" radius="0.01"/>
        </geometry>
        <material name="red"/>
      </visual>

      <collision>
        <origin rpy="0 0 0" xyz="0 0 0"/>
        <geometry>
          <cylinder length="0.220" radius="0.01"/>
        </geometry>
      </collision>

      <inertial>
        <origin rpy="0 0 0" xyz="0 0 0"/>
        <mass value="0.25"/>
        <inertia ixx="0.0010145833333333333" ixy="0.0" ixz="0.0" iyy="0.0010145833333333333" iyz="0.0" izz="1.25e-05" />
      </inertial>

  </link>

  <joint name="joint_bar_4" type="fixed">
    <origin rpy="0 0 0" xyz="-0.05 0.120 0.185"/>
    <parent link="base_link"/>
    <child link="left_back_support_link"/>
  </joint>

    <link name="head">  
      <visual>
        <origin rpy="0 0 0" xyz="0 0 0"/>
        <geometry>
          <cylinder length="0.09" radius="0.160"/>
        </geometry>
      </visual>

      <collision>
        <origin rpy="0 0 0" xyz="0 0 0"/>
        <geometry>
          <cylinder length="0.09" radius="0.160"/>
        </geometry>
      </collision>

      <inertial>
        <origin rpy="0 0 0" xyz="0 0 0"/>
        <mass value="1.5"/>
        <inertia ixx="0.0106125" ixy="0.0" ixz="0.0" iyy="0.0106125" iyz="0.0" izz="0.019200000000000002" />
      </inertial>
    </link>

  <joint name="head_joint" type="fixed">
    <origin rpy="0 0 0" xyz="0 0 0.2975"/>
    <parent link="base_link"/>
    <child link="head"/>
  </joint> 

  <!-- JOINT PUBLISHER -->
  <gazebo>
    <plugin name="bot_joint_state" filename="libgazebo_ros_joint_state_publisher.so">
      <ros>
          <remapping>~/out:=joint_states</remapping>
      </ros>
      <update_rate>30</update_rate>

      <joint_name>joint_left_wheel</joint_name>
      <joint_name>joint_right_wheel</joint_name>
      <joint_name>front_yaw_joint</joint_name>
      <joint_name>back_yaw_joint</joint_name>
      <joint_name>front_roll_joint</joint_name>
      <joint_name>back_roll_joint</joint_name>
      <joint_name>front_pitch_joint</joint_name>
      <joint_name>back_pitch_joint</joint_name>
      
    </plugin>
  </gazebo>
  <!-- Differential drive -->
  <gazebo>
    <plugin filename="libgazebo_ros_diff_drive.so" name="differential_drive_controller">

      <!-- wheels -->
      <left_joint>joint_left_wheel</left_joint>
      <right_joint>joint_right_wheel</right_joint>

      <!-- kinematics -->
      <wheel_separation>0.1625</wheel_separation>
      <wheel_diameter>0.06</wheel_diameter>

      <!-- limits -->
      <max_wheel_torque>1.0</max_wheel_torque>
      <max_wheel_acceleration>1.0</max_wheel_acceleration>

      <!-- output -->
      <publish_odom>true</publish_odom>
      <publish_odom_tf>true</publish_odom_tf>

      <odometry_frame>odom</odometry_frame>
      <robot_base_frame>base_link</robot_base_frame>

    </plugin>
  </gazebo>

  <link name="laser_scan_link">
    <visual>
      <origin rpy="0 0 0" xyz="0 0 -0.021"/>
      <geometry>
        <mesh filename="file://$(find barista_robot_description)/meshes/rplidar_a2.dae" scale="1 1 1"/> 
        <!-- <cylinder length="0.03" radius="0.025"/> -->
      </geometry>
    </visual>

    <collision>
       <origin rpy="0 0 0" xyz="0 0 0"/>
      <geometry>
        <cylinder length="0.042" radius="0.038"/>
      </geometry>
    </collision>

    <inertial>
      <origin rpy="0 0 0" xyz="0 0 0"/>
      <mass value="0.3"/>
      <inertia ixx="6.9375e-05" ixy="0.0" ixz="0.0" iyy="6.9375e-05" iyz="0.0" izz="9.375000000000002e-05" />
     </inertial>

  </link>

  <joint name="laser_scan_link_joint" type="fixed">
    <origin rpy="0 0 0" xyz="0.11 0 0.0925"/>
    <parent link="base_link"/>
    <child link="laser_scan_link"/>
    <axis xyz="0 0 0"/>
  </joint>

  <!-- Sensors -->
  <gazebo reference="laser_scan_link">
    <sensor name="sensor_ray" type="ray">
        <pose>0 0 0 0 0 0</pose>
        <ray>
          <scan>
            <horizontal>
              <samples>200</samples>
              <resolution>1.0</resolution>
              <min_angle>-3.14</min_angle>
              <max_angle>3.14</max_angle>
            </horizontal>
          </scan>
          <range>
            <min>0.04</min>
            <max>16.0</max>
          </range>
        </ray>
        <always_on>true</always_on>
        <visualize>true</visualize>
        <update_rate>100.0</update_rate>
        <plugin name="laser" filename="libgazebo_ros_ray_sensor.so">
          <ros>
            <remapping>~/out:=scan</remapping>
          </ros>
          <output_type>sensor_msgs/LaserScan</output_type>
        </plugin>
    </sensor>
    </gazebo>

</robot>